<mujoco model="so_arm101">
  <compiler angle="radian" meshdir="assets" autolimits="true"/>

  <option integrator="implicitfast" cone="elliptic" impratio="10"/>

  <asset>
    <material name="so101_yellow" rgba="1.0 0.82 0.12 1"/>
    <material name="servo_black" rgba="0.1 0.1 0.1 1"/>
    <material name="collision_green" rgba="0 1 0 0.35"/>
    <material name="pad_dark" rgba="0.05 0.05 0.05 1"/>

    <mesh name="base_motor_holder_so101_v1" file="base_motor_holder_so101_v1.stl"/>
    <mesh name="base_so101_v2" file="base_so101_v2.stl"/>
    <mesh name="sts3215_03a_v1" file="sts3215_03a_v1.stl"/>
    <mesh name="waveshare_mounting_plate_so101_v2" file="waveshare_mounting_plate_so101_v2.stl"/>
    <mesh name="motor_holder_so101_base_v1" file="motor_holder_so101_base_v1.stl"/>
    <mesh name="rotation_pitch_so101_v1" file="rotation_pitch_so101_v1.stl"/>
    <mesh name="upper_arm_so101_v1" file="upper_arm_so101_v1.stl"/>
    <mesh name="under_arm_so101_v1" file="under_arm_so101_v1.stl"/>
    <mesh name="motor_holder_so101_wrist_v1" file="motor_holder_so101_wrist_v1.stl"/>
    <mesh name="sts3215_03a_no_horn_v1" file="sts3215_03a_no_horn_v1.stl"/>
    <mesh name="wrist_roll_pitch_so101_v2" file="wrist_roll_pitch_so101_v2.stl"/>
    <mesh name="wrist_roll_follower_so101_v1" file="wrist_roll_follower_so101_v1.stl"/>
    <mesh name="moving_jaw_so101_v1" file="moving_jaw_so101_v1.stl"/>
  </asset>

  <default>
    <default class="so_arm101">
      <geom condim="1" contype="0" conaffinity="0"/>
      <site rgba="1 0 0 1" size="0.006" group="5"/>
      <joint damping="0.1" frictionloss="0.01"/>
      <default class="visual">
        <geom type="mesh" group="2"/>
      </default>
      <default class="collision">
        <geom group="3" material="collision_green" contype="1" conaffinity="1"
          condim="6" friction="1 0.005 0.0005" solref="0.004 1"
          solimp="0.95 0.99 0.001" priority="1" mass="0"/>
      </default>
      <default class="fingertip_collision">
        <geom type="box" group="3" material="pad_dark" contype="1" conaffinity="1"
          condim="6" friction="1 0.005 0.0005" solref="0.004 1"
          solimp="0.95 0.99 0.001" priority="1" mass="0"
          size="0.006 0.0025 0.014"/>
      </default>
    </default>
  </default>

  <worldbody>
    <body name="base_link" childclass="so_arm101">
      <inertial pos="0.0137179 -5.19711e-05 0.0334843" mass="0.147"
        diaginertia="0.000114686 0.000136117 0.000130364"/>
      <geom class="visual" mesh="base_motor_holder_so101_v1" material="so101_yellow"
        pos="-0.00636471 -9.94414e-05 -0.0024" euler="1.5708 -1.67685e-15 1.5708"/>
      <geom class="visual" mesh="base_so101_v2" material="so101_yellow"
        pos="-0.00636471 -8.97657e-09 -0.0024" euler="1.5708 -2.78073e-29 1.5708"/>
      <geom class="visual" mesh="sts3215_03a_v1" material="servo_black"
        pos="0.0263353 -8.97657e-09 0.0437" euler="-8.21148e-16 7.84513e-18 1.249e-15"/>
      <geom class="visual" mesh="waveshare_mounting_plate_so101_v2" material="so101_yellow"
        pos="-0.0309827 -0.000199441 0.0474" euler="1.5708 -1.35493e-14 1.5708"/>

      <body name="shoulder_link" pos="0.0388353 -8.97657e-09 0.0624" euler="3.14159 4.18253e-17 -3.14159">
        <inertial pos="-0.0307604 -1.66727e-05 -0.0252713" mass="0.100006"
          diaginertia="8.3759e-05 8.10403e-05 2.39783e-05"/>
        <joint name="shoulder_pan" axis="0 0 1" range="-1.91986 1.91986"/>
        <geom class="visual" mesh="sts3215_03a_v1" material="servo_black"
          pos="-0.0303992 0.000422241 -0.0417" euler="1.5708 1.5708 0"/>
        <geom class="visual" mesh="motor_holder_so101_base_v1" material="so101_yellow"
          pos="-0.0675992 -0.000177759 0.0158499" euler="1.5708 -1.5708 0"/>
        <geom class="visual" mesh="rotation_pitch_so101_v1" material="so101_yellow"
          pos="0.0122008 2.22413e-05 0.0464" euler="-1.5708 2.35221e-33 0"/>

        <body name="upper_arm_link" pos="-0.0303992 -0.0182778 -0.0542" euler="-1.5708 -1.5708 0">
          <inertial pos="-0.0898471 -0.00838224 0.0184089" mass="0.103"
            diaginertia="4.08002e-05 0.000147318 0.000142487"/>
          <joint name="shoulder_lift" axis="0 0 1" range="-1.74533 1.74533"/>
          <geom class="visual" mesh="sts3215_03a_v1" material="servo_black"
            pos="-0.11257 -0.0155 0.0187" euler="-3.14159 -5.27356e-16 -1.5708"/>
          <geom class="visual" mesh="upper_arm_so101_v1" material="so101_yellow"
            pos="-0.065085 0.012 0.0182" euler="3.14159 0 -1.30911e-30"/>

          <body name="lower_arm_link" pos="-0.11257 -0.028 1.73763e-16" euler="-3.63608e-16 8.74301e-16 1.5708">
            <inertial pos="-0.0980701 0.00324376 0.0182831" mass="0.104"
              diaginertia="2.87438e-05 0.000159844 0.00014529"/>
            <joint name="elbow_flex" axis="0 0 1" range="-1.69 1.69"/>
            <geom class="visual" mesh="under_arm_so101_v1" material="so101_yellow"
              pos="-0.0648499 -0.032 0.0182" euler="3.14159 0 6.67202e-31"/>
            <geom class="visual" mesh="motor_holder_so101_wrist_v1" material="so101_yellow"
              pos="-0.0648499 -0.032 0.018" euler="-3.14159 -2.55351e-15 -1.83387e-30"/>
            <geom class="visual" mesh="sts3215_03a_v1" material="servo_black"
              pos="-0.1224 0.0052 0.0187" euler="-3.14159 -7.88861e-31 -3.14159"/>

            <body name="wrist_link" pos="-0.1349 0.0052 3.62355e-17" euler="4.02456e-15 8.67362e-16 -1.5708">
              <inertial pos="-0.000103312 -0.0386143 0.0281156" mass="0.079"
                diaginertia="3.68263e-05 2.5391e-05 2.1e-05"/>
              <joint name="wrist_flex" axis="0 0 1" range="-1.65806 1.65806"/>
              <geom class="visual" mesh="sts3215_03a_no_horn_v1" material="servo_black"
                pos="8.32667e-17 -0.0424 0.0306" euler="1.5708 1.5708 0"/>
              <geom class="visual" mesh="wrist_roll_pitch_so101_v2" material="so101_yellow"
                pos="0 -0.028 0.0181" euler="-1.5708 -1.5708 0"/>

              <body name="gripper_link" pos="5.55112e-17 -0.0611 0.0181" euler="1.5708 0.0486795 3.14159">
                <inertial pos="0.000213627 0.000245138 -0.025187" mass="0.087"
                  diaginertia="2.75087e-05 4.33657e-05 3.45059e-05"/>
                <joint name="wrist_roll" axis="0 0 1" range="-2.74385 2.84121"/>
                <geom class="visual" mesh="sts3215_03a_v1" material="servo_black"
                  pos="0.0077 0.0001 -0.0234" euler="-1.5708 -5.19179e-17 -1.66533e-16"/>
                <geom class="visual" mesh="wrist_roll_follower_so101_v1" material="so101_yellow"
                  pos="8.32667e-17 -0.000218214 0.000949706" euler="-3.14159 -5.55112e-17 0"/>
                <geom name="fixed_fingertip_collision" class="fingertip_collision"
                  pos="-0.0079 -0.009 -0.082" euler="0 0 0"/>
                <site name="gripper_frame" pos="-0.0079 -0.000218121 -0.0981274" euler="0 3.14159 0"/>

                <body name="moving_jaw_so101_v1_link" pos="0.0202 0.0188 -0.0234" euler="1.5708 -5.24284e-08 -1.41553e-15">
                  <inertial pos="-0.00157495 -0.0300244 0.0192755" mass="0.012"
                    diaginertia="6.61427e-06 1.89032e-06 5.28738e-06"/>
                  <joint name="gripper" axis="0 0 1" range="-0.174533 1.74533"/>
                  <geom class="visual" mesh="moving_jaw_so101_v1" material="so101_yellow"
                    pos="-5.55112e-17 -5.55112e-17 0.0189" euler="9.53145e-17 6.93889e-18 1.24077e-24"/>
                  <geom name="moving_fingertip_collision" class="fingertip_collision"
                    pos="-0.001 -0.030 0.019" euler="0 0 0"/>
                </body>
              </body>
            </body>
          </body>
        </body>
      </body>
    </body>
  </worldbody>

  <contact>
    <exclude name="exclude_base_shoulder" body1="base_link" body2="shoulder_link"/>
  </contact>

  <keyframe>
    <key name="home" qpos="0 0 0 0 0 0.8"/>
  </keyframe>
</mujoco>
